<?xml version='1.0'?>
<sdf version='1.6'>
  <model name='hunter_killer_mast'>
    <!--link name='box_base'>
      <pose frame=''>0 0 0 0 -0 0</pose>
      <inertial>
        <pose frame=''>0 0 0 0 -0 0</pose>
        <mass>20</mass>
        <inertia>
          <ixx>4</ixx>
          <ixy>0</ixy>
          <ixz>0</ixz>
          <iyy>4</iyy>
          <iyz>0</iyz>
          <izz>4</izz>
        </inertia>
      </inertial>
      <collision name='box_base_collision'>
        <pose frame=''>0 0 0 0 -0 0</pose>
        <geometry>
          <box>
            <size>1 1 0.1</size>
          </box>
        </geometry>
      </collision>
      <visual name='box_base_visual'>
        <pose frame=''>0 0 0 0 -0 0</pose>
        <geometry>
          <box>
            <size>1 1 0.1</size>
          </box>
        </geometry>
        <material>
          <script>
            <name>ModelPreview_1::base::base_visual_MATERIAL_</name>
          </script>
          <ambient>0.4 0.4 0.4 1</ambient>
          <shader type='vertex'>
            <normal_map>__default__</normal_map>
          </shader>
          <diffuse>0.9 0.9 0.9 1</diffuse>
          <specular>0.2 0.2 0.2 1</specular>
          <emissive>0 0 0 1</emissive>
        </material>
      </visual>
    </link-->

    <!-- DroneShip -->

    <link name='link_0'>
      <inertial>
        <mass>10000</mass>
        <inertia>
          <ixx>10000</ixx>
          <ixy>0</ixy>
          <ixz>0</ixz>
          <iyy>10000</iyy>
          <iyz>0</iyz>
          <izz>10000</izz>
        </inertia>
      </inertial>
      <pose frame=''>0.055548 0.074743 -0.469586 -1.59323 0 0</pose>
      <visual name='visual'>
        <pose frame=''>0 0 0 0 -0 0</pose>
        <geometry>
          <mesh>
            <uri>/home/gangadhar/Downloads/Drone Ship Base.stl</uri>
            <scale>1 1 1</scale>
          </mesh>
        </geometry>
        <material>
          <lighting>1</lighting>
          <script>
            <uri>file://media/materials/scripts/gazebo.material</uri>
            <name>Gazebo/Grey</name>
          </script>
        </material>
        <transparency>0</transparency>
        <cast_shadows>1</cast_shadows>
      </visual>
      <collision name='collision'>
        <laser_retro>0</laser_retro>
        <max_contacts>10</max_contacts>
        <pose frame=''>0 0 0 0 -0 0</pose>
        <geometry>
          <mesh>
            <uri>/home/gangadhar/Downloads/Drone Ship Base.stl</uri>
            <scale>1 1 1</scale>
          </mesh>
        </geometry>
        <surface>
          <friction>
            <ode>
              <mu>1</mu>
              <mu2>1</mu2>
              <fdir1>0 0 0</fdir1>
              <slip1>0</slip1>
              <slip2>0</slip2>
            </ode>
            <torsional>
              <coefficient>1</coefficient>
              <patch_radius>0</patch_radius>
              <surface_radius>0</surface_radius>
              <use_patch_radius>1</use_patch_radius>
              <ode>
                <slip>0</slip>
              </ode>
            </torsional>
          </friction>
          <bounce>
            <restitution_coefficient>0</restitution_coefficient>
            <threshold>1e+06</threshold>
          </bounce>
          <contact>
            <collide_without_contact>0</collide_without_contact>
            <collide_without_contact_bitmask>1</collide_without_contact_bitmask>
            <collide_bitmask>1</collide_bitmask>
            <ode>
              <soft_cfm>0</soft_cfm>
              <soft_erp>0.2</soft_erp>
              <kp>1e+13</kp>
              <kd>1</kd>
              <max_vel>0.01</max_vel>
              <min_depth>0</min_depth>
            </ode>
            <bullet>
              <split_impulse>1</split_impulse>
              <split_impulse_penetration_threshold>-0.01</split_impulse_penetration_threshold>
              <soft_cfm>0</soft_cfm>
              <soft_erp>0.2</soft_erp>
              <kp>1e+13</kp>
              <kd>1</kd>
            </bullet>
          </contact>
        </surface>
      </collision>
    </link>
    <link name='link_1'>
      <inertial>
        <mass>10000</mass>
        <inertia>
          <ixx>10000</ixx>
          <ixy>0</ixy>
          <ixz>0</ixz>
          <iyy>10000</iyy>
          <iyz>0</iyz>
          <izz>10000</izz>
        </inertia>
      </inertial>
      <pose frame=''>-0.038817 -0.079302 -0.447148 1.56287 -0 0</pose>
      <visual name='visual'>
        <pose frame=''>0 0 0 0 -0 0</pose>
        <geometry>
          <mesh>
            <uri>/home/gangadhar/Downloads/Drone Ship part 2.stl</uri>
            <scale>1 1 1</scale>
          </mesh>
        </geometry>
        <material>
          <lighting>1</lighting>
          <script>
            <uri>file://media/materials/scripts/gazebo.material</uri>
            <name>Gazebo/Grey</name>
          </script>
        </material>
        <transparency>0</transparency>
        <cast_shadows>1</cast_shadows>
      </visual>
      <collision name='collision'>
        <laser_retro>0</laser_retro>
        <max_contacts>10</max_contacts>
        <pose frame=''>0 0 0 0 -0 0</pose>
        <geometry>
          <mesh>
            <uri>/home/gangadhar/Downloads/Drone Ship part 2.stl</uri>
            <scale>1 1 1</scale>
          </mesh>
        </geometry>
        <surface>
          <friction>
            <ode>
              <mu>1</mu>
              <mu2>1</mu2>
              <fdir1>0 0 0</fdir1>
              <slip1>0</slip1>
              <slip2>0</slip2>
            </ode>
            <torsional>
              <coefficient>1</coefficient>
              <patch_radius>0</patch_radius>
              <surface_radius>0</surface_radius>
              <use_patch_radius>1</use_patch_radius>
              <ode>
                <slip>0</slip>
              </ode>
            </torsional>
          </friction>
          <bounce>
            <restitution_coefficient>0</restitution_coefficient>
            <threshold>1e+06</threshold>
          </bounce>
          <contact>
            <collide_without_contact>0</collide_without_contact>
            <collide_without_contact_bitmask>1</collide_without_contact_bitmask>
            <collide_bitmask>1</collide_bitmask>
            <ode>
              <soft_cfm>0</soft_cfm>
              <soft_erp>0.2</soft_erp>
              <kp>1e+13</kp>
              <kd>1</kd>
              <max_vel>0.01</max_vel>
              <min_depth>0</min_depth>
            </ode>
            <bullet>
              <split_impulse>1</split_impulse>
              <split_impulse_penetration_threshold>-0.01</split_impulse_penetration_threshold>
              <soft_cfm>0</soft_cfm>
              <soft_erp>0.2</soft_erp>
              <kp>1e+13</kp>
              <kd>1</kd>
            </bullet>
          </contact>
        </surface>
      </collision>
    </link>
    <link name='link_2'>
      <inertial>
        <mass>10000</mass>
        <inertia>
          <ixx>10000</ixx>
          <ixy>0</ixy>
          <ixz>0</ixz>
          <iyy>10000</iyy>
          <iyz>0</iyz>
          <izz>10000</izz>
        </inertia>
      </inertial>
      <pose frame=''>-9.5532 -0.057565 -0.438942 1.55624 -0 0</pose>
      <visual name='visual'>
        <pose frame=''>0 0 0 0 -0 0</pose>
        <geometry>
          <mesh>
            <uri>/home/gangadhar/Downloads/Just Read The Instructions Part 1.stl</uri>
            <scale>1 1 1</scale>
          </mesh>
        </geometry>
        <material>
          <lighting>1</lighting>
          <script>
            <uri>file://media/materials/scripts/gazebo.material</uri>
            <name>Gazebo/Grey</name>
          </script>
        </material>
        <transparency>0</transparency>
        <cast_shadows>1</cast_shadows>
      </visual>
      <collision name='collision'>
        <laser_retro>0</laser_retro>
        <max_contacts>10</max_contacts>
        <pose frame=''>0 0 0 0 -0 0</pose>
        <geometry>
          <mesh>
            <uri>/home/gangadhar/Downloads/Just Read The Instructions Part 1.stl</uri>
            <scale>1 1 1</scale>
          </mesh>
        </geometry>
        <surface>
          <friction>
            <ode>
              <mu>1</mu>
              <mu2>1</mu2>
              <fdir1>0 0 0</fdir1>
              <slip1>0</slip1>
              <slip2>0</slip2>
            </ode>
            <torsional>
              <coefficient>1</coefficient>
              <patch_radius>0</patch_radius>
              <surface_radius>0</surface_radius>
              <use_patch_radius>1</use_patch_radius>
              <ode>
                <slip>0</slip>
              </ode>
            </torsional>
          </friction>
          <bounce>
            <restitution_coefficient>0</restitution_coefficient>
            <threshold>1e+06</threshold>
          </bounce>
          <contact>
            <collide_without_contact>0</collide_without_contact>
            <collide_without_contact_bitmask>1</collide_without_contact_bitmask>
            <collide_bitmask>1</collide_bitmask>
            <ode>
              <soft_cfm>0</soft_cfm>
              <soft_erp>0.2</soft_erp>
              <kp>1e+13</kp>
              <kd>1</kd>
              <max_vel>0.01</max_vel>
              <min_depth>0</min_depth>
            </ode>
            <bullet>
              <split_impulse>1</split_impulse>
              <split_impulse_penetration_threshold>-0.01</split_impulse_penetration_threshold>
              <soft_cfm>0</soft_cfm>
              <soft_erp>0.2</soft_erp>
              <kp>1e+13</kp>
              <kd>1</kd>
            </bullet>
          </contact>
        </surface>
      </collision>
    </link>
    <link name='link_3'>
      <inertial>
        <mass>10000</mass>
        <inertia>
          <ixx>10000</ixx>
          <ixy>0</ixy>
          <ixz>0</ixz>
          <iyy>10000</iyy>
          <iyz>0</iyz>
          <izz>10000</izz>
        </inertia>
      </inertial>
      <pose frame=''>0.051094 0.007434 2.02223 -1.5872 0 0</pose>
      <visual name='visual'>
        <pose frame=''>0 0 0 0 -0 0</pose>
        <geometry>
          <mesh>
            <uri>/home/gangadhar/Downloads/Railing.stl</uri>
            <scale>1 1 1</scale>
          </mesh>
        </geometry>
        <material>
          <lighting>1</lighting>
          <script>
            <uri>file://media/materials/scripts/gazebo.material</uri>
            <name>Gazebo/Grey</name>
          </script>
        </material>
        <transparency>0</transparency>
        <cast_shadows>1</cast_shadows>
      </visual>
      <collision name='collision'>
        <laser_retro>0</laser_retro>
        <max_contacts>10</max_contacts>
        <pose frame=''>0 0 0 0 -0 0</pose>
        <geometry>
          <mesh>
            <uri>/home/gangadhar/Downloads/Railing.stl</uri>
            <scale>1 1 1</scale>
          </mesh>
        </geometry>
        <surface>
          <friction>
            <ode>
              <mu>1</mu>
              <mu2>1</mu2>
              <fdir1>0 0 0</fdir1>
              <slip1>0</slip1>
              <slip2>0</slip2>
            </ode>
            <torsional>
              <coefficient>1</coefficient>
              <patch_radius>0</patch_radius>
              <surface_radius>0</surface_radius>
              <use_patch_radius>1</use_patch_radius>
              <ode>
                <slip>0</slip>
              </ode>
            </torsional>
          </friction>
          <bounce>
            <restitution_coefficient>0</restitution_coefficient>
            <threshold>1e+06</threshold>
          </bounce>
          <contact>
            <collide_without_contact>0</collide_without_contact>
            <collide_without_contact_bitmask>1</collide_without_contact_bitmask>
            <collide_bitmask>1</collide_bitmask>
            <ode>
              <soft_cfm>0</soft_cfm>
              <soft_erp>0.2</soft_erp>
              <kp>1e+13</kp>
              <kd>1</kd>
              <max_vel>0.01</max_vel>
              <min_depth>0</min_depth>
            </ode>
            <bullet>
              <split_impulse>1</split_impulse>
              <split_impulse_penetration_threshold>-0.01</split_impulse_penetration_threshold>
              <soft_cfm>0</soft_cfm>
              <soft_erp>0.2</soft_erp>
              <kp>1e+13</kp>
              <kd>1</kd>
            </bullet>
          </contact>
        </surface>
      </collision>
    </link>
    <link name='link_4'>
      <inertial>
        <mass>10000</mass>
        <inertia>
          <ixx>10000</ixx>
          <ixy>0</ixy>
          <ixz>0</ixz>
          <iyy>10000</iyy>
          <iyz>0</iyz>
          <izz>10000</izz>
        </inertia>
      </inertial>
      <pose frame=''>9.48535 0.054699 -0.666566 1.58388 0.000281 -3.1322</pose>
      <visual name='visual'>
        <pose frame=''>0 0 0 0 -0 0</pose>
        <geometry>
          <mesh>
            <uri>/home/gangadhar/Downloads/Just Read The Instructions Part 1.stl</uri>
            <scale>1 1 1</scale>
          </mesh>
        </geometry>
        <material>
          <lighting>1</lighting>
          <script>
            <uri>file://media/materials/scripts/gazebo.material</uri>
            <name>Gazebo/Grey</name>
          </script>
        </material>
        <transparency>0</transparency>
        <cast_shadows>1</cast_shadows>
      </visual>
      <collision name='collision'>
        <laser_retro>0</laser_retro>
        <max_contacts>10</max_contacts>
        <pose frame=''>0 0 0 0 -0 0</pose>
        <geometry>
          <mesh>
            <uri>/home/gangadhar/Downloads/Just Read The Instructions Part 1.stl</uri>
            <scale>1 1 1</scale>
          </mesh>
        </geometry>
        <surface>
          <friction>
            <ode>
              <mu>1</mu>
              <mu2>1</mu2>
              <fdir1>0 0 0</fdir1>
              <slip1>0</slip1>
              <slip2>0</slip2>
            </ode>
            <torsional>
              <coefficient>1</coefficient>
              <patch_radius>0</patch_radius>
              <surface_radius>0</surface_radius>
              <use_patch_radius>1</use_patch_radius>
              <ode>
                <slip>0</slip>
              </ode>
            </torsional>
          </friction>
          <bounce>
            <restitution_coefficient>0</restitution_coefficient>
            <threshold>1e+06</threshold>
          </bounce>
          <contact>
            <collide_without_contact>0</collide_without_contact>
            <collide_without_contact_bitmask>1</collide_without_contact_bitmask>
            <collide_bitmask>1</collide_bitmask>
            <ode>
              <soft_cfm>0</soft_cfm>
              <soft_erp>0.2</soft_erp>
              <kp>1e+13</kp>
              <kd>1</kd>
              <max_vel>0.01</max_vel>
              <min_depth>0</min_depth>
            </ode>
            <bullet>
              <split_impulse>1</split_impulse>
              <split_impulse_penetration_threshold>-0.01</split_impulse_penetration_threshold>
              <soft_cfm>0</soft_cfm>
              <soft_erp>0.2</soft_erp>
              <kp>1e+13</kp>
              <kd>1</kd>
            </bullet>
          </contact>
        </surface>
      </collision>
    </link>

    <joint name='joint1' type='prismatic'>
      <child>link_1</child>
      <parent>link_0</parent>
      <axis>
        <xyz>0 0 0</xyz>
        <limit>
          <lower>0.0</lower>
          <upper>0.0</upper>
          <effort>0.0</effort>
          <velocity>0.0</velocity>
        </limit>
        <dynamics>
          <spring_reference>0</spring_reference>
          <spring_stiffness>0</spring_stiffness>
        </dynamics>
        <use_parent_model_frame>1</use_parent_model_frame>
      </axis>
    </joint>

    <joint name='joint2' type='prismatic'>
      <child>link_2</child>
      <parent>link_1</parent>
      <axis>
        <xyz>0 0 0</xyz>
        <limit>
          <lower>0.0</lower>
          <upper>0.0</upper>
          <effort>0.0</effort>
          <velocity>0.0</velocity>
        </limit>
        <dynamics>
          <spring_reference>0</spring_reference>
          <spring_stiffness>0</spring_stiffness>
        </dynamics>
        <use_parent_model_frame>1</use_parent_model_frame>
      </axis>
    </joint>

    <joint name='joint3' type='prismatic'>
      <child>link_4</child>
      <parent>link_1</parent>
      <axis>
        <xyz>0 0 0</xyz>
        <limit>
          <lower>0.0</lower>
          <upper>0.0</upper>
          <effort>0</effort>
          <velocity>0.0</velocity>
        </limit>
        <dynamics>
          <spring_reference>0</spring_reference>
          <spring_stiffness>0</spring_stiffness>
        </dynamics>
        <use_parent_model_frame>1</use_parent_model_frame>
      </axis>
    </joint>

    <joint name='joint4' type='prismatic'>
      <child>link_3</child>
      <parent>link_1</parent>
      <axis>
        <xyz>0 0 0</xyz>
        <limit>
          <lower>0.0</lower>
          <upper>0.0</upper>
          <effort>0</effort>
          <velocity>0.0</velocity>
        </limit>
        <dynamics>
          <spring_reference>0</spring_reference>
          <spring_stiffness>0</spring_stiffness>
        </dynamics>
        <use_parent_model_frame>1</use_parent_model_frame>
      </axis>
    </joint>

    <!-- Droneship Close-->


    <link name='base'>
      <pose frame=''>0 0 0.05 0 -0 0</pose>
      <inertial>
        <pose frame=''>-0.021807 0.298116 0.306153 0 -0 0</pose>
        <mass>26.6735</mass>
        <inertia>
          <ixx>2.29538</ixx>
          <ixy>-9.71572e-19</ixy>
          <ixz>-2.66211e-17</ixz>
          <iyy>4.58898</iyy>
          <iyz>0</iyz>
          <izz>2.29538</izz>
        </inertia>
      </inertial>
      <collision name='base_collision'>
        <pose frame=''>-0.25 0.3 0 0 -0 0</pose>
        <geometry>
          <mesh>
            <scale>1 1 1</scale>
            <uri>/home/gangadhar/IARC_ws/src/hunter_killer_mast/meshes/base.STL</uri>
          </mesh>
        </geometry>
      </collision>
    </link>

    <joint name='roll_joint' type='revolute'>
      <child>base</child>
      <parent>link_1</parent>
      <axis>
        <xyz>1 0 0</xyz>
        <limit>
          <lower>-0.2</lower>
          <upper>0.2</upper>
          <effort>1000</effort>
          <velocity>0.5</velocity>
        </limit>
        <dynamics>
          <damping>0.0001</damping>
          <friction>0.0001</friction>
          <spring_reference>0</spring_reference>
          <spring_stiffness>0</spring_stiffness>
        </dynamics>
        <use_parent_model_frame>1</use_parent_model_frame>
      </axis>
    </joint>
    
    <link name='mast'>
      <pose frame=''>0 0 0.05 0 -0 0</pose>
      <inertial>
        <pose frame=''>-0.001482 -0.028214 0.755526 -3.14159 -1.0464 -1.0472</pose>
        <mass>4.50868</mass>
        <inertia>
          <ixx>0.278217</ixx>
          <ixy>-0.0121037</ixy>
          <ixz>0.369556</ixz>
          <iyy>0.959113</iyy>
          <iyz>0.0251943</iyz>
          <izz>0.786576</izz>
        </inertia>
      </inertial>
      <collision name='mast_collision'>
        <pose frame=''>0 0.05 0.714 -3.14159 -1.0464 -1.0472</pose>
        <geometry>
          <mesh>
            <scale>1 1 1</scale>
            <uri>/home/gangadhar/IARC_ws/src/hunter_killer_mast/meshes/mast.STL</uri>
          </mesh>
        </geometry>
      </collision>
      <collision name='mast_fixed_joint_lump__blue_board_collision_1'>
        <pose frame=''>-0.01 -0.13 1.05 1.5708 -0 0</pose>
        <geometry>
          <mesh>
            <scale>1 1 1</scale>
            <uri>/home/gangadhar/IARC_ws/src/hunter_killer_mast/meshes/blue_board.STL</uri>
          </mesh>
        </geometry>
      </collision>
      <collision name='mast_fixed_joint_lump__name_plate_collision_2'>
        <pose frame=''>-0.01 -0.132794 1.13382 -4e-06 0 0</pose>
        <geometry>
          <mesh>
            <scale>1 1 1</scale>
            <uri>/home/gangadhar/IARC_ws/src/hunter_killer_mast/meshes/name_plate.STL</uri>
          </mesh>
        </geometry>
      </collision>
      <collision name='mast_fixed_joint_lump__rod_supporter_collision_3'>
        <pose frame=''>-0.01 -0.13 1.05 1.5708 -0 0</pose>
        <geometry>
          <mesh>
            <scale>1 1 1</scale>
            <uri>/home/gangadhar/IARC_ws/src/hunter_killer_mast/meshes/rod_supporter.STL</uri>
          </mesh>
        </geometry>
      </collision>
      <collision name='mast_fixed_joint_lump__communication_module_collision_4'>
        <pose frame=''>0.0027 -0.18254 1.05 0.053011 3e-06 -1.5708</pose>
        <geometry>
          <mesh>
            <scale>1 1 1</scale>
            <uri>/home/gangadhar/IARC_ws/src/hunter_killer_mast/meshes/communication_module.STL</uri>
          </mesh>
        </geometry>
      </collision>
      <collision name='mast_fixed_joint_lump__antena_collision_5'>
        <pose frame=''>0.434503 -0.19858 1.05252 3.14151 3e-06 -1.5708</pose>
        <geometry>
          <mesh>
            <scale>1 1 1</scale>
            <uri>/home/gangadhar/IARC_ws/src/hunter_killer_mast/meshes/antena.STL</uri>
          </mesh>
        </geometry>
      </collision>
      <collision name='mast_fixed_joint_lump__exposed_plate_collision_6'>
        <pose frame=''>-0.01 -0.23414 1.05 3.14159 1.57079 -3e-06</pose>
        <geometry>
          <mesh>
            <scale>1 1 1</scale>
            <uri>/home/gangadhar/IARC_ws/src/hunter_killer_mast/meshes/exposed_plate.STL</uri>
          </mesh>
        </geometry>
      </collision>
      <collision name='mast_fixed_joint_lump__guide_rods_collision_7'>
        <pose frame=''>-0.01 -0.13 1.05 1.5708 -0 0</pose>
        <geometry>
          <mesh>
            <scale>1 1 1</scale>
            <uri>/home/gangadhar/IARC_ws/src/hunter_killer_mast/meshes/guide_rods.STL</uri>
          </mesh>
        </geometry>
      </collision>
      <collision name='mast_fixed_joint_lump__navigation_pole_collision_8'>
        <pose frame=''>-0.508 -0.05 1.43 3.14159 1.57079 3.14159</pose>
        <geometry>
          <mesh>
            <scale>1 1 1</scale>
            <uri>/home/gangadhar/IARC_ws/src/hunter_killer_mast/meshes/navigation_pole.STL</uri>
          </mesh>
        </geometry>
      </collision>
      <collision name='mast_fixed_joint_lump__ledport_collision_9'>
        <pose frame=''>0.48 -0.046 1.48 0 -0 0</pose>
        <geometry>
          <mesh>
            <scale>1 1 1</scale>
            <uri>/home/gangadhar/IARC_ws/src/hunter_killer_mast/meshes/base_led.STL</uri>
          </mesh>
        </geometry>
      </collision>
      <collision name='mast_fixed_joint_lump__ledstarboard_collision_10'>
        <pose frame=''>-0.52 -0.046 1.48 0 -0 0</pose>
        <geometry>
          <mesh>
            <scale>1 1 1</scale>
            <uri>/home/gangadhar/IARC_ws/src/hunter_killer_mast/meshes/base_led.STL</uri>
          </mesh>
        </geometry>
      </collision>
      <visual name='mast_visual'>
        <pose frame=''>0 0.05 0.714 -3.14159 -1.0464 -1.0472</pose>
        <geometry>
          <mesh>
            <scale>1 1 1</scale>
            <uri>/home/gangadhar/IARC_ws/src/hunter_killer_mast/meshes/mast.STL</uri>
          </mesh>
        </geometry>
        <material>
          <shader type='vertex'>
            <normal_map>__default__</normal_map>
          </shader>
          <script>
            <name>ModelPreview_1::base::base_fixed_joint_lump__mast_visual_1_MATERIAL_</name>
          </script>
          <ambient>0.4 0.4 0.4 1</ambient>
          <diffuse>0.8 0.8 0.8 1</diffuse>
          <specular>0.4 0.4 0.4 1</specular>
          <emissive>0 0 0 1</emissive>
        </material>
      </visual>
      <visual name='mast_fixed_joint_lump__blue_board_visual_1'>
        <pose frame=''>-0.01 -0.13 1.05 1.5708 -0 0</pose>
        <geometry>
          <mesh>
            <scale>1 1 1</scale>
            <uri>/home/gangadhar/IARC_ws/src/hunter_killer_mast/meshes/blue_board.STL</uri>
          </mesh>
        </geometry>
        <material>
          <shader type='vertex'>
            <normal_map>__default__</normal_map>
          </shader>
          <script>
            <name>ModelPreview_1::base::base_fixed_joint_lump__blue_board_visual_2_MATERIAL_</name>
          </script>
          <ambient>0.225 0.3 0.35 1</ambient>
          <diffuse>0.45 0.6 0.7 1</diffuse>
          <specular>0.2 0.2 0.2 1</specular>
          <emissive>0 0 0 1</emissive>
        </material>
      </visual>
      <visual name='mast_fixed_joint_lump__name_plate_visual_2'>
        <pose frame=''>-0.01 -0.132794 1.13382 -4e-06 0 0</pose>
        <geometry>
          <box>
            <size>0.26 0.001 0.062</size>
          </box>
        </geometry>
        <material>
          <script>
            <uri>/home/gangadhar/IARC_ws/src/hunter_killer_mast/materials/byu.material</uri>
            <name>BYU/ground</name>
          </script>
        </material>
      </visual>
      <visual name='mast_fixed_joint_lump__rod_supporter_visual_3'>
        <pose frame=''>-0.01 -0.13 1.05 1.5708 -0 0</pose>
        <geometry>
          <mesh>
            <scale>1 1 1</scale>
            <uri>/home/gangadhar/IARC_ws/src/hunter_killer_mast/meshes/rod_supporter.STL</uri>
          </mesh>
        </geometry>
        <material>
          <shader type='vertex'>
            <normal_map>__default__</normal_map>
          </shader>
          <script>
            <name>ModelPreview_1::base::base_fixed_joint_lump__rod_supporter_visual_4_MATERIAL_</name>
          </script>
          <ambient>0.225 0.3 0.35 1</ambient>
          <diffuse>0.45 0.6 0.7 1</diffuse>
          <specular>0.2 0.2 0.2 1</specular>
          <emissive>0 0 0 1</emissive>
        </material>
      </visual>
      <visual name='mast_fixed_joint_lump__communication_module_visual_4'>
        <pose frame=''>0.0027 -0.18254 1.05 0.053011 3e-06 -1.5708</pose>
        <geometry>
          <mesh>
            <scale>1 1 1</scale>
            <uri>/home/gangadhar/IARC_ws/src/hunter_killer_mast/meshes/communication_module.STL</uri>
          </mesh>
        </geometry>
        <material>
          <shader type='vertex'>
            <normal_map>__default__</normal_map>
          </shader>
          <script>
            <name>ModelPreview_1::base::base_fixed_joint_lump__communication_module_visual_5_MATERIAL_</name>
          </script>
          <ambient>0.225 0.3 0.35 1</ambient>
          <diffuse>0.45 0.6 0.7 1</diffuse>
          <specular>0.2 0.2 0.2 1</specular>
          <emissive>0 0 0 1</emissive>
        </material>
      </visual>
      <visual name='mast_fixed_joint_lump__antena_visual_5'>
        <pose frame=''>0.434503 -0.19858 1.05252 3.14151 3e-06 -1.5708</pose>
        <geometry>
          <mesh>
            <scale>1 1 1</scale>
            <uri>/home/gangadhar/IARC_ws/src/hunter_killer_mast/meshes/antena.STL</uri>
          </mesh>
        </geometry>
        <material>
          <shader type='vertex'>
            <normal_map>__default__</normal_map>
          </shader>
          <script>
            <name>ModelPreview_1::base::base_fixed_joint_lump__antena_visual_6_MATERIAL_</name>
          </script>
          <ambient>0.4 0.4 0.4 1</ambient>
          <diffuse>0.8 0.8 0.8 1</diffuse>
          <specular>0.4 0.4 0.4 1</specular>
          <emissive>0 0 0 1</emissive>
        </material>
      </visual>
      <visual name='mast_fixed_joint_lump__exposed_plate_visual_6'>
        <pose frame=''>-0.01 -0.23414 1.05 3.14159 1.57079 -3e-06</pose>
        <geometry>
          <mesh>
            <scale>1 1 1</scale>
            <uri>/home/gangadhar/IARC_ws/src/hunter_killer_mast/meshes/exposed_plate.STL</uri>
          </mesh>
        </geometry>
        <material>
          <script>
            <name>Gazebo/Red</name>
            <uri>file://media/materials/scripts/gazebo.material</uri>
          </script>
        </material>
      </visual>
      <visual name='mast_fixed_joint_lump__guide_rods_visual_7'>
        <pose frame=''>-0.01 -0.13 1.05 1.5708 -0 0</pose>
        <geometry>
          <mesh>
            <scale>1 1 1</scale>
            <uri>/home/gangadhar/IARC_ws/src/hunter_killer_mast/meshes/guide_rods.STL</uri>
          </mesh>
        </geometry>
        <material>
          <shader type='vertex'>
            <normal_map>__default__</normal_map>
          </shader>
          <script>
            <name>ModelPreview_1::base::base_fixed_joint_lump__guide_rods_visual_8_MATERIAL_</name>
          </script>
          <ambient>0.225 0.3 0.35 1</ambient>
          <diffuse>0.45 0.6 0.7 1</diffuse>
          <specular>0.2 0.2 0.2 1</specular>
          <emissive>0 0 0 1</emissive>
        </material>
      </visual>
      <visual name='mast_fixed_joint_lump__navigation_pole_visual_8'>
        <pose frame=''>-0.508 -0.05 1.43 3.14159 1.57079 3.14159</pose>
        <geometry>
          <mesh>
            <scale>1 1 1</scale>
            <uri>/home/gangadhar/IARC_ws/src/hunter_killer_mast/meshes/navigation_pole.STL</uri>
          </mesh>
        </geometry>
        <material>
          <shader type='vertex'>
            <normal_map>__default__</normal_map>
          </shader>
          <script>
            <name>ModelPreview_1::base::base_fixed_joint_lump__navigation_pole_visual_9_MATERIAL_</name>
          </script>
          <ambient>0.4 0.4 0.4 1</ambient>
          <diffuse>0.8 0.8 0.8 1</diffuse>
          <specular>0.4 0.4 0.4 1</specular>
          <emissive>0 0 0 1</emissive>
        </material>
      </visual>
      <visual name='mast_fixed_joint_lump__ledport_visual_9'>
        <pose frame=''>0.48 -0.046 1.48 0 -0 0</pose>
        <geometry>
          <mesh>
            <scale>1 1 1</scale>
            <uri>/home/gangadhar/IARC_ws/src/hunter_killer_mast/meshes/base_led.STL</uri>
          </mesh>
        </geometry>
        <material>
          <shader type='vertex'>
            <normal_map>__default__</normal_map>
          </shader>
          <script>
            <name>ModelPreview_1::base::base_fixed_joint_lump__navigation_pole_visual_9_MATERIAL_</name>
          </script>
          <ambient>0.4 0.4 0.4 1</ambient>
          <diffuse>0.8 0.8 0.8 1</diffuse>
          <specular>0.4 0.4 0.4 1</specular>
          <emissive>0 0 0 1</emissive>
        </material>
      </visual>
      <visual name='mast_fixed_joint_lump__ledstarboard_visual_10'>
        <pose frame=''>-0.52 -0.046 1.48 0 -0 0</pose>
        <geometry>
          <mesh>
            <scale>1 1 1</scale>
            <uri>/home/gangadhar/IARC_ws/src/hunter_killer_mast/meshes/base_led.STL</uri>
          </mesh>
        </geometry>
        <material>
          <shader type='vertex'>
            <normal_map>__default__</normal_map>
          </shader>
          <script>
            <name>ModelPreview_1::base::base_fixed_joint_lump__navigation_pole_visual_9_MATERIAL_</name>
          </script>
          <ambient>0.4 0.4 0.4 1</ambient>
          <diffuse>0.8 0.8 0.8 1</diffuse>
          <specular>0.4 0.4 0.4 1</specular>
          <emissive>0 0 0 1</emissive>
        </material>
      </visual>
    </link>
    <joint name='pitch_joint' type='revolute'>
      <child>mast</child>
      <parent>base</parent>
      <axis>
        <xyz>0 1 0</xyz>
        <limit>
          <lower>-0.2</lower>
          <upper>0.2</upper>
          <effort>1000</effort>
          <velocity>0.5</velocity>
        </limit>
        <dynamics>
          <damping>0.0001</damping>
          <friction>0.0001</friction>
          <spring_reference>0</spring_reference>
          <spring_stiffness>0</spring_stiffness>
        </dynamics>
        <use_parent_model_frame>1</use_parent_model_frame>
      </axis>
    </joint>

<!--

    <link name='hemi1l'>
      <pose frame=''>0.499003 -0.046 1.5028 1.5708 -0 -1.4136</pose>
      <inertial>
        <pose frame=''>0.003137 0 0.000497 0 -0 0</pose>
        <mass>0.03418</mass>
        <inertia>
          <ixx>0.000356543</ixx>
          <ixy>6.61061e-10</ixy>
          <ixz>1.58901e-15</ixz>
          <iyy>0.00054688</iyy>
          <iyz>2.2761e-10</iyz>
          <izz>0.000356543</izz>
        </inertia>
      </inertial>
      <collision name='hemi1l_collision'>
        <pose frame=''>0 0 0 0 -0 0</pose>
        <geometry>
          <mesh>
            <scale>1 1 1</scale>
            <uri>/home/gangadhar/IARC_ws/src/hunter_killer_mast/meshes/hemi1.STL</uri>
          </mesh>
        </geometry>
        <surface>
          <contact>
            <ode/>
          </contact>
          <friction>
            <ode/>
          </friction>
        </surface>
      </collision>
      <collision name='hemi1l_fixed_joint_lump__hemi2l_collision_1'>
        <pose frame=''>0.003137 0 0.000497 -3.14159 1.2392 -0</pose>
        <geometry>
          <mesh>
            <scale>1 1 1</scale>
            <uri>/home/gangadhar/IARC_ws/src/hunter_killer_mast/meshes/hemi2.STL</uri>
          </mesh>
        </geometry>
      </collision>
      <visual name='hemi1l_visual'>
        <pose frame=''>0 0 0 0 -0 0</pose>
        <geometry>
          <mesh>
            <scale>1 1 1</scale>
            <uri>/home/gangadhar/IARC_ws/src/hunter_killer_mast/meshes/hemi1.STL</uri>
          </mesh>
        </geometry>
        <material> 
          <ambient>0.1 0.1 0.1 1</ambient>
          <diffuse>0.1 0.1 0.1 1</diffuse>
          <specular>0 1 0 1</specular>
          <emissive>0 1 0 1</emissive>
        </material> 
      </visual>
      <visual name='hemi1l_fixed_joint_lump__hemi2l_visual_1'>
        <pose frame=''>0.003137 0 0.000497 -3.14159 1.2392 -0</pose>
        <geometry>
          <mesh>
            <scale>1 1 1</scale>
            <uri>/home/gangadhar/IARC_ws/src/hunter_killer_mast/meshes/hemi2.STL</uri>
          </mesh>
        </geometry>
        <material> 
          <ambient>0.7 0.8 0.7 0.9</ambient>
          <diffuse>0.7 0.8 0.7 0.9</diffuse>
          <specular>1 1 1 0.9</specular>
          <emissive>0 0 0 0</emissive>
        </material> 
      </visual>
      <gravity>1</gravity>
      <velocity_decay/>
    </link>

    <joint name='hemi1l_joint' type='revolute'>
      <child>hemi1l</child>
      <parent>mast</parent>
      <axis>
        <xyz>0.015655 -0.098767 0</xyz>
        <limit>
          <lower>0</lower>
          <upper>3.1416</upper>
          <effort>10</effort>
          <velocity>10</velocity>
        </limit>
        <dynamics>
          <spring_reference>0</spring_reference>
          <spring_stiffness>0</spring_stiffness>
        </dynamics>
        <use_parent_model_frame>1</use_parent_model_frame>
      </axis>
    </joint>

    <link name='hemi1r'>
      <pose frame=''>-0.500997 -0.046 1.5028 1.5708 -0 -1.4136</pose>
      <inertial>
        <pose frame=''>0.003137 0 0.000497 0 -0 0</pose>
        <mass>0.03418</mass>
        <inertia>
          <ixx>0.000356543</ixx>
          <ixy>6.61061e-10</ixy>
          <ixz>1.58901e-15</ixz>
          <iyy>0.00054688</iyy>
          <iyz>2.2761e-10</iyz>
          <izz>0.000356543</izz>
        </inertia>
      </inertial>
      <collision name='hemi1r_collision'>
        <pose frame=''>0 0 0 0 -0 0</pose>
        <geometry>
          <mesh>
            <scale>1 1 1</scale>
            <uri>/home/gangadhar/IARC_ws/src/hunter_killer_mast/meshes/hemi1.STL</uri>
          </mesh>
        </geometry>
        <surface>
          <contact>
            <ode/>
          </contact>
          <friction>
            <ode/>
          </friction>
        </surface>
      </collision>
      <collision name='hemi1r_fixed_joint_lump__hemi2r_collision_1'>
        <pose frame=''>0.003137 0 0.000497 -3.14159 1.2392 -0</pose>
        <geometry>
          <mesh>
            <scale>1 1 1</scale>
            <uri>/home/gangadhar/IARC_ws/src/hunter_killer_mast/meshes/hemi2.STL</uri>
          </mesh>
        </geometry>
      </collision>
      <visual name='hemi1r_visual'>
        <pose frame=''>0 0 0 0 -0 0</pose>
        <geometry>
          <mesh>
            <scale>1 1 1</scale>
            <uri>/home/gangadhar/IARC_ws/src/hunter_killer_mast/meshes/hemi1.STL</uri>
          </mesh>
        </geometry>
        <material> 
          <ambient>0.1 0.1 0.1 1</ambient>
          <diffuse>0.1 0.1 0.1 1</diffuse>
          <specular>1 0 0 1</specular>
          <emissive>1 0 0 1</emissive>
        </material> 
      </visual>
      <visual name='hemi1r_fixed_joint_lump__hemi2r_visual_1'>
        <pose frame=''>0.003137 0 0.000497 -3.14159 1.2392 -0</pose>
        <geometry>
          <mesh>
            <scale>1 1 1</scale>
            <uri>/home/gangadhar/IARC_ws/src/hunter_killer_mast/meshes/hemi2.STL</uri>
          </mesh>
        </geometry>
        <material> 
          <ambient>0.8 0.7 0.7 0.9</ambient>
          <diffuse>0.8 0.7 0.7 0.9</diffuse>
          <specular>1 1 1 0.9</specular>
          <emissive>0 0 0 0</emissive>
        </material> 
      </visual>
      <gravity>1</gravity>
      <velocity_decay/>
    </link>
    <joint name='hemi1r_joint' type='revolute'>
      <child>hemi1r</child>
      <parent>mast</parent>
      <axis>
        <xyz>0.015655 -0.098767 0</xyz>
        <limit>
          <lower>0</lower>
          <upper>3.1416</upper>
          <effort>10</effort>
          <velocity>10</velocity>
        </limit>
        <dynamics>
          <spring_reference>0</spring_reference>
          <spring_stiffness>0</spring_stiffness>
        </dynamics>
        <use_parent_model_frame>1</use_parent_model_frame>
      </axis>
    </joint>

-->

    <link name='pankha'>
      <pose frame=''>0 -0.03 2.1 0 -0 0</pose>
      <inertial>
        <pose frame=''>0 0 -0 0 -0 0</pose>
        <mass>3.73075</mass>
        <inertia>
          <ixx>0.0101974</ixx>
          <ixy>0</ixy>
          <ixz>8.84709e-18</ixz>
          <iyy>0.326023</iyy>
          <iyz>5.60136e-20</iyz>
          <izz>0.326023</izz>
        </inertia>
      </inertial>
      <collision name='pankha_collision'>
        <pose frame=''>-0.508 0 0 0 -0 0</pose>
        <geometry>
          <mesh>
            <scale>1 1 1</scale>
            <uri>/home/gangadhar/IARC_ws/src/hunter_killer_mast/meshes/pankha.STL</uri>
          </mesh>
        </geometry>
      </collision>
      <visual name='pankha_visual'>
        <pose frame=''>-0.508 0 0 0 -0 0</pose>
        <geometry>
          <mesh>
            <scale>1 1 1</scale>
            <uri>/home/gangadhar/IARC_ws/src/hunter_killer_mast/meshes/pankha.STL</uri>
          </mesh>
        </geometry>
        <material>
          <shader type='vertex'>
            <normal_map>__default__</normal_map>
          </shader>
          <script>
            <name>ModelPreview_1::base::base_fixed_joint_lump__pankha_visual_10_MATERIAL_</name>
          </script>
          <ambient>0.4 0.4 0.4 1</ambient>
          <diffuse>0.8 0.8 0.8 1</diffuse>
          <specular>0.4 0.4 0.4 1</specular>
          <emissive>0 0 0 1</emissive>
        </material>
      </visual>
    </link>

    <joint name='pankha_joint' type='revolute'>
      <child>pankha</child>
      <parent>mast</parent>
      <axis>
        <xyz>0 0 1</xyz>
        <limit>
          <lower>-1e+11</lower>
          <upper>1e+11</upper>
          <effort>1</effort>
          <velocity>1</velocity>
        </limit>
        <dynamics>
          <spring_reference>0</spring_reference>
          <spring_stiffness>0</spring_stiffness>
        </dynamics>
        <use_parent_model_frame>1</use_parent_model_frame>
      </axis>
    </joint>

    <static>0</static>
    <plugin name='gazebo_ros_control' filename='libgazebo_ros_control.so'>
      <robotNamespace>/hunter_killer_mast</robotNamespace>
    </plugin>
  </model>
</sdf>